Workbook

Sheet 使い方
A1: 電気工事 現場計算ツールキット（無料版） v1.0
A3: ■ 使い方
A4: ・黄色セル（青字）に入力すると、水色セルが自動計算されます。1行目の「例）」行は上書きしてOKです。
A5: ・プルダウンのあるセルはリストから選んでください。
A7: ■ シート構成
A8: ・電圧降下 …… 配電方式・電流・こう長・断面積から電圧降下/降下率を計算し、許容値を満たす推奨サイズを表示
A9: ・参照表 …… 計算に使う係数・基準値の一覧（出典つき）
A11: ■ 計算の根拠
A12: ・電圧降下: 内線規程の簡易式 e = K×L×I ÷ (1000×A)（銅線・力率1・平衡負荷を想定）
A14: ■ 製品版（有料）にはこちらも入っています
A15: ・許容電流の自動判定（電流減少係数・周囲温度補正）
A16: ・材料拾い出し表 → 見積書まで自動連動（インボイス対応）
... A19: 【免責】本ツールは設計・積算の補助を目的とした概算ツールです。最終判断は最新の電気設備技術基準・同解釈・内線規程・メーカー資料・所轄電力会社の規定に基づき、有資格者が行ってください。

Sheet 電圧降下
A1: 電圧降下・電線サイズ計算
A2: 凡例: 黄色セル（青字）＝入力欄 ／ 水色セル＝自動計算 ／ それ以外は触らないでください
A3: e = K×L×I ÷ (1000×A) K: 単相2線35.6／単相3線17.8／三相3線30.8（内線規程の簡易式・銅線）
A5: 回路名 | B5: 配電方式 | C5: 基準電圧 V | D5: 電流 A | E5: こう長 m | F5: 電線断面積 mm² | G5: 許容降下率 | H5: 係数K | I5: 電圧降下 V | J5: 降下率 | K5: 判定 | L5: 必要断面積 mm² | M5: 推奨サイズ mm²
A6: 例）1F照明 | B6: 単相2線式 | C6: 100 | D6: 12 | E6: 35 | F6: 3.5 | G6: 0.02 | H6: =IFERROR(INDEX(参照表!$B$5:$B$7,MATCH(B6,参照表!$A$5:$A$7,0)),"") | I6: =IF(OR(B6="",D6="",E6="",F6="",N(F6)<=0),"",H6*E6*D6/(1000*F6)) | J6: =IF(OR(I6="",C6="",N(C6)<=0),"",I6/C6) | K6: =IF(OR(J6="",G6=""),"",IF(J6<=G6,"OK","NG")) | L6: =IF(OR(H6="",D6="",E6="",C6="",G6="",N(C6)<=0,N(G6)<=0),"",H6*E6*D6/(1000*C6*G6)) | M6: =IF(L6="","",IF(L6>MAX(参照表!$A$12:$A$24),"要検討",INDEX(参照表!$A$12:$A$24,COUNTIF(参照表!$A$12:$A$24,"<"&L6)+1)))
H7: =IFERROR(INDEX(参照表!$B$5:$B$7,MATCH(B7,参照表!$A$5:$A$7,0)),"") | I7: =IF(OR(B7="",D7="",E7="",F7="",N(F7)<=0),"",H7*E7*D7/(1000*F7)) | J7: =IF(OR(I7="",C7="",N(C7)<=0),"",I7/C7) | K7: =IF(OR(J7="",G7=""),"",IF(J7<=G7,"OK","NG")) | L7: =IF(OR(H7="",D7="",E7="",C7="",G7="",N(C7)<=0,N(G7)<=0),"",H7*E7*D7/(1000*C7*G7)) | M7: =IF(L7="","",IF(L7>MAX(参照表!$A$12:$A$24),"要検討",INDEX(参照表!$A$12:$A$24,COUNTIF(参照表!$A$12:$A$24,"<"&L7)+1)))
H8: =IFERROR(INDEX(参照表!$B$5:$B$7,MATCH(B8,参照表!$A$5:$A$7,0)),"") | I8: =IF(OR(B8="",D8="",E8="",F8="",N(F8)<=0),"",H8*E8*D8/(1000*F8)) | J8: =IF(OR(I8="",C8="",N(C8)<=0),"",I8/C8) | K8: =IF(OR(J8="",G8=""),"",IF(J8<=G8,"OK","NG")) | L8: =IF(OR(H8="",D8="",E8="",C8="",G8="",N(C8)<=0,N(G8)<=0),"",H8*E8*D8/(1000*C8*G8)) | M8: =IF(L8="","",IF(L8>MAX(参照表!$A$12:$A$24),"要検討",INDEX(参照表!$A$12:$A$24,COUNTIF(参照表!$A$12:$A$24,"<"&L8)+1)))
H9: =IFERROR(INDEX(参照表!$B$5:$B$7,MATCH(B9,参照表!$A$5:$A$7,0)),"") | I9: =IF(OR(B9="",D9="",E9="",F9="",N(F9)<=0),"",H9*E9*D9/(1000*F9)) | J9: =IF(OR(I9="",C9="",N(C9)<=0),"",I9/C9) | K9: =IF(OR(J9="",G9=""),"",IF(J9<=G9,"OK","NG")) | L9: =IF(OR(H9="",D9="",E9="",C9="",G9="",N(C9)<=0,N(G9)<=0),"",H9*E9*D9/(1000*C9*G9)) | M9: =IF(L9="","",IF(L9>MAX(参照表!$A$12:$A$24),"要検討",INDEX(参照表!$A$12:$A$24,COUNTIF(参照表!$A$12:$A$24,"<"&L9)+1)))
H10: =IFERROR(INDEX(参照表!$B$5:$B$7,MATCH(B10,参照表!$A$5:$A$7,0)),"") | I10: =IF(OR(B10="",D10="",E10="",F10="",N(F10)<=0),"",H10*E10*D10/(1000*F10)) | J10: =IF(OR(I10="",C10="",N(C10)<=0),"",I10/C10) | K10: =IF(OR(J10="",G10=""),"",IF(J10<=G10,"OK","NG")) | L10: =IF(OR(H10="",D10="",E10="",C10="",G10="",N(C10)<=0,N(G10)<=0),"",H10*E10*D10/(1000*C10*G10)) | M10: =IF(L10="","",IF(L10>MAX(参照表!$A$12:$A$24),"要検討",INDEX(参照表!$A$12:$A$24,COUNTIF(参照表!$A$12:$A$24,"<"&L10)+1)))
H11: =IFERROR(INDEX(参照表!$B$5:$B$7,MATCH(B11,参照表!$A$5:$A$7,0)),"") | I11: =IF(OR(B11="",D11="",E11="",F11="",N(F11)<=0),"",H11*E11*D11/(1000*F11)) | J11: =IF(OR(I11="",C11="",N(C11)<=0),"",I11/C11) | K11: =IF(OR(J11="",G11=""),"",IF(J11<=G11,"OK","NG")) | L11: =IF(OR(H11="",D11="",E11="",C11="",G11="",N(C11)<=0,N(G11)<=0),"",H11*E11*D11/(1000*C11*G11)) | M11: =IF(L11="","",IF(L11>MAX(参照表!$A$12:$A$24),"要検討",INDEX(参照表!$A$12:$A$24,COUNTIF(参照表!$A$12:$A$24,"<"&L11)+1)))
H12: =IFERROR(INDEX(参照表!$B$5:$B$7,MATCH(B12,参照表!$A$5:$A$7,0)),"") | I12: =IF(OR(B12="",D12="",E12="",F12="",N(F12)<=0),"",H12*E12*D12/(1000*F12)) | J12: =IF(OR(I12="",C12="",N(C12)<=0),"",I12/C12) | K12: =IF(OR(J12="",G12=""),"",IF(J12<=G12,"OK","NG")) | L12: =IF(OR(H12="",D12="",E12="",C12="",G12="",N(C12)<=0,N(G12)<=0),"",H12*E12*D12/(1000*C12*G12)) | M12: =IF(L12="","",IF(L12>MAX(参照表!$A$12:$A$24),"要検討",INDEX(参照表!$A$12:$A$24,COUNTIF(参照表!$A$12:$A$24,"<"&L12)+1)))
H13: =IFERROR(INDEX(参照表!$B$5:$B$7,MATCH(B13,参照表!$A$5:$A$7,0)),"") | I13: =IF(OR(B13="",D13="",E13="",F13="",N(F13)<=0),"",H13*E13*D13/(1000*F13)) | J13: =IF(OR(I13="",C13="",N(C13)<=0),"",I13/C13) | K13: =IF(OR(J13="",G13=""),"",IF(J13<=G13,"OK","NG")) | L13: =IF(OR(H13="",D13="",E13="",C13="",G13="",N(C13)<=0,N(G13)<=0),"",H13*E13*D13/(1000*C13*G13)) | M13: =IF(L13="","",IF(L13>MAX(参照表!$A$12:$A$24),"要検討",INDEX(参照表!$A$12:$A$24,COUNTIF(参照表!$A$12:$A$24,"<"&L13)+1)))
H14: =IFERROR(INDEX(参照表!$B$5:$B$7,MATCH(B14,参照表!$A$5:$A$7,0)),"") | I14: =IF(OR(B14="",D14="",E14="",F14="",N(F14)<=0),"",H14*E14*D14/(1000*F14)) | J14: =IF(OR(I14="",C14="",N(C14)<=0),"",I14/C14) | K14: =IF(OR(J14="",G14=""),"",IF(J14<=G14,"OK","NG")) | L14: =IF(OR(H14="",D14="",E14="",C14="",G14="",N(C14)<=0,N(G14)<=0),"",H14*E14*D14/(1000*C14*G14)) | M14: =IF(L14="","",IF(L14>MAX(参照表!$A$12:$A$24),"要検討",INDEX(参照表!$A$12:$A$24,COUNTIF(参照表!$A$12:$A$24,"<"&L14)+1)))
H15: =IFERROR(INDEX(参照表!$B$5:$B$7,MATCH(B15,参照表!$A$5:$A$7,0)),"") | I15: =IF(OR(B15="",D15="",E15="",F15="",N(F15)<=0),"",H15*E15*D15/(1000*F15)) | J15: =IF(OR(I15="",C15="",N(C15)<=0),"",I15/C15) | K15: =IF(OR(J15="",G15=""),"",IF(J15<=G15,"OK","NG")) | L15: =IF(OR(H15="",D15="",E15="",C15="",G15="",N(C15)<=0,N(G15)<=0),"",H15*E15*D15/(1000*C15*G15)) | M15: =IF(L15="","",IF(L15>MAX(参照表!$A$12:$A$24),"要検討",INDEX(参照表!$A$12:$A$24,COUNTIF(参照表!$A$12:$A$24,"<"&L15)+1)))
H16: =IFERROR(INDEX(参照表!$B$5:$B$7,MATCH(B16,参照表!$A$5:$A$7,0)),"") | I16: =IF(OR(B16="",D16="",E16="",F16="",N(F16)<=0),"",H16*E16*D16/(1000*F16)) | J16: =IF(OR(I16="",C16="",N(C16)<=0),"",I16/C16) | K16: =IF(OR(J16="",G16=""),"",IF(J16<=G16,"OK","NG")) | L16: =IF(OR(H16="",D16="",E16="",C16="",G16="",N(C16)<=0,N(G16)<=0),"",H16*E16*D16/(1000*C16*G16)) | M16: =IF(L16="","",IF(L16>MAX(参照表!$A$12:$A$24),"要検討",INDEX(参照表!$A$12:$A$24,COUNTIF(参照表!$A$12:$A$24,"<"&L16)+1)))
H17: =IFERROR(INDEX(参照表!$B$5:$B$7,MATCH(B17,参照表!$A$5:$A$7,0)),"") | I17: =IF(OR(B17="",D17="",E17="",F17="",N(F17)<=0),"",H17*E17*D17/(1000*F17)) | J17: =IF(OR(I17="",C17="",N(C17)<=0),"",I17/C17) | K17: =IF(OR(J17="",G17=""),"",IF(J17<=G17,"OK","NG")) | L17: =IF(OR(H17="",D17="",E17="",C17="",G17="",N(C17)<=0,N(G17)<=0),"",H17*E17*D17/(1000*C17*G17)) | M17: =IF(L17="","",IF(L17>MAX(参照表!$A$12:$A$24),"要検討",INDEX(参照表!$A$12:$A$24,COUNTIF(参照表!$A$12:$A$24,"<"&L17)+1)))
H18: =IFERROR(INDEX(参照表!$B$5:$B$7,MATCH(B18,参照表!$A$5:$A$7,0)),"") | I18: =IF(OR(B18="",D18="",E18="",F18="",N(F18)<=0),"",H18*E18*D18/(1000*F18)) | J18: =IF(OR(I18="",C18="",N(C18)<=0),"",I18/C18) | K18: =IF(OR(J18="",G18=""),"",IF(J18<=G18,"OK","NG")) | L18: =IF(OR(H18="",D18="",E18="",C18="",G18="",N(C18)<=0,N(G18)<=0),"",H18*E18*D18/(1000*C18*G18)) | M18: =IF(L18="","",IF(L18>MAX(参照表!$A$12:$A$24),"要検討",INDEX(参照表!$A$12:$A$24,COUNTIF(参照表!$A$12:$A$24,"<"&L18)+1)))
... H25: =IFERROR(INDEX(参照表!$B$5:$B$7,MATCH(B25,参照表!$A$5:$A$7,0)),"") | I25: =IF(OR(B25="",D25="",E25="",F25="",N(F25)<=0),"",H25*E25*D25/(1000*F25)) | J25: =IF(OR(I25="",C25="",N(C25)<=0),"",I25/C25) | K25: =IF(OR(J25="",G25=""),"",IF(J25<=G25,"OK","NG")) | L25: =IF(OR(H25="",D25="",E25="",C25="",G25="",N(C25)<=0,N(G25)<=0),"",H25*E25*D25/(1000*C25*G25)) | M25: =IF(L25="","",IF(L25>MAX(参照表!$A$12:$A$24),"要検討",INDEX(参照表!$A$12:$A$24,COUNTIF(参照表!$A$12:$A$24,"<"&L25)+1)))
A27: 【免責】本ツールは設計・積算の補助を目的とした概算ツールです。最終判断は最新の電気設備技術基準・同解釈・内線規程・メーカー資料・所轄電力会社の規定に基づき、有資格者が行ってください。

Sheet 参照表
A1: 参照表（計算シートから参照しています。数値を変える場合は最新の基準で確認のうえ）
A3: ① 配電方式と電圧降下の係数K（e = K×L×I ÷ (1000×A)）
A4: 配電方式 | B4: 係数K
A5: 単相2線式 | B5: 35.6 | C5: 単相3線式は中性線と外線の間の降下（平衡負荷）
A6: 単相3線式 | B6: 17.8
A7: 三相3線式 | B7: 30.8
A10: ② 標準電線断面積（mm²）
A11: 断面積mm²
A12: 2 | B12: 単線の断面積: 1.6mm=2.0 / 2.0mm=3.14 / 2.6mm=5.31 / 3.2mm=8.04 mm²
A13: 3.5
A14: 5.5
A15: 8
A16: 14
A17: 22
A18: 38
A19: 60
A20: 100
A21: 150
A22: 200
A23: 250
A24: 325
A27: ③ 許容電流（電技解釈 表146-1 基準値・周囲温度30℃）
A28: 電線 | B28: 許容電流A
A29: 単線 1.6mm | B29: 27
A30: 単線 2.0mm | B30: 35
A31: 単線 2.6mm | B31: 48
A32: 単線 3.2mm | B32: 62
A33: より線 2mm² | B33: 27
A34: より線 3.5mm² | B34: 37
A35: より線 5.5mm² | B35: 49
A36: より線 8mm² | B36: 61
A37: より線 14mm² | B37: 88
A38: より線 22mm² | B38: 115
A39: より線 38mm² | B39: 162
A40: より線 60mm² | B40: 217
A41: より線 100mm² | B41: 298
A44: ④ 電流減少係数（電技解釈 表146-3）
A45: 同一管内の電線数 | B45: 係数
A46: 管に収めない（がいし引き等） | B46: 1
A47: 3本以下 | B47: 0.7
...
