Workbook

Sheet 使い方
A1: 電気工事 現場計算ツールキット v1.0
A3: ■ 使い方
A4: ・黄色セル（青字）に入力すると、水色セルが自動計算されます。1行目の「例）」行は上書きしてOKです。
A5: ・プルダウンのあるセルはリストから選んでください。
A7: ■ シート構成
A8: ・電圧降下 …… 配電方式・電流・こう長・断面積から電圧降下/降下率を計算し、許容値を満たす推奨サイズを表示
A9: ・許容電流 …… 電線の許容電流を電流減少係数・周囲温度で補正し、負荷電流とOK/NG判定
A10: ・材料拾い …… 部屋/区画ごとの数量からロス率込みの合計数量と材料費を集計
A11: ・見積書 …… 材料拾いの材料費を自動で取り込み、税込金額まで計算（インボイス登録番号欄あり）。印刷範囲設定済み
A12: ・参照表 …… 計算に使う係数・基準値の一覧（出典つき）
A14: ■ 計算の根拠
A15: ・電圧降下: 内線規程の簡易式 e = K×L×I ÷ (1000×A)（銅線・力率1・平衡負荷を想定）
... A18: 【免責】本ツールは設計・積算の補助を目的とした概算ツールです。最終判断は最新の電気設備技術基準・同解釈・内線規程・メーカー資料・所轄電力会社の規定に基づき、有資格者が行ってください。

Sheet 電圧降下
A1: 電圧降下・電線サイズ計算
A2: 凡例: 黄色セル（青字）＝入力欄 ／ 水色セル＝自動計算 ／ それ以外は触らないでください
A3: e = K×L×I ÷ (1000×A) K: 単相2線35.6／単相3線17.8／三相3線30.8（内線規程の簡易式・銅線）
A5: 回路名 | B5: 配電方式 | C5: 基準電圧 V | D5: 電流 A | E5: こう長 m | F5: 電線断面積 mm² | G5: 許容降下率 | H5: 係数K | I5: 電圧降下 V | J5: 降下率 | K5: 判定 | L5: 必要断面積 mm² | M5: 推奨サイズ mm²
A6: 例）1F照明 | B6: 単相2線式 | C6: 100 | D6: 12 | E6: 35 | F6: 3.5 | G6: 0.02 | H6: =IFERROR(INDEX(参照表!$B$5:$B$7,MATCH(B6,参照表!$A$5:$A$7,0)),"") | I6: =IF(OR(B6="",D6="",E6="",F6="",N(F6)<=0),"",H6*E6*D6/(1000*F6)) | J6: =IF(OR(I6="",C6="",N(C6)<=0),"",I6/C6) | K6: =IF(OR(J6="",G6=""),"",IF(J6<=G6,"OK","NG")) | L6: =IF(OR(H6="",D6="",E6="",C6="",G6="",N(C6)<=0,N(G6)<=0),"",H6*E6*D6/(1000*C6*G6)) | M6: =IF(L6="","",IF(L6>MAX(参照表!$A$12:$A$24),"要検討",INDEX(参照表!$A$12:$A$24,COUNTIF(参照表!$A$12:$A$24,"<"&L6)+1)))
H7: =IFERROR(INDEX(参照表!$B$5:$B$7,MATCH(B7,参照表!$A$5:$A$7,0)),"") | I7: =IF(OR(B7="",D7="",E7="",F7="",N(F7)<=0),"",H7*E7*D7/(1000*F7)) | J7: =IF(OR(I7="",C7="",N(C7)<=0),"",I7/C7) | K7: =IF(OR(J7="",G7=""),"",IF(J7<=G7,"OK","NG")) | L7: =IF(OR(H7="",D7="",E7="",C7="",G7="",N(C7)<=0,N(G7)<=0),"",H7*E7*D7/(1000*C7*G7)) | M7: =IF(L7="","",IF(L7>MAX(参照表!$A$12:$A$24),"要検討",INDEX(参照表!$A$12:$A$24,COUNTIF(参照表!$A$12:$A$24,"<"&L7)+1)))
H8: =IFERROR(INDEX(参照表!$B$5:$B$7,MATCH(B8,参照表!$A$5:$A$7,0)),"") | I8: =IF(OR(B8="",D8="",E8="",F8="",N(F8)<=0),"",H8*E8*D8/(1000*F8)) | J8: =IF(OR(I8="",C8="",N(C8)<=0),"",I8/C8) | K8: =IF(OR(J8="",G8=""),"",IF(J8<=G8,"OK","NG")) | L8: =IF(OR(H8="",D8="",E8="",C8="",G8="",N(C8)<=0,N(G8)<=0),"",H8*E8*D8/(1000*C8*G8)) | M8: =IF(L8="","",IF(L8>MAX(参照表!$A$12:$A$24),"要検討",INDEX(参照表!$A$12:$A$24,COUNTIF(参照表!$A$12:$A$24,"<"&L8)+1)))
H9: =IFERROR(INDEX(参照表!$B$5:$B$7,MATCH(B9,参照表!$A$5:$A$7,0)),"") | I9: =IF(OR(B9="",D9="",E9="",F9="",N(F9)<=0),"",H9*E9*D9/(1000*F9)) | J9: =IF(OR(I9="",C9="",N(C9)<=0),"",I9/C9) | K9: =IF(OR(J9="",G9=""),"",IF(J9<=G9,"OK","NG")) | L9: =IF(OR(H9="",D9="",E9="",C9="",G9="",N(C9)<=0,N(G9)<=0),"",H9*E9*D9/(1000*C9*G9)) | M9: =IF(L9="","",IF(L9>MAX(参照表!$A$12:$A$24),"要検討",INDEX(参照表!$A$12:$A$24,COUNTIF(参照表!$A$12:$A$24,"<"&L9)+1)))
H10: =IFERROR(INDEX(参照表!$B$5:$B$7,MATCH(B10,参照表!$A$5:$A$7,0)),"") | I10: =IF(OR(B10="",D10="",E10="",F10="",N(F10)<=0),"",H10*E10*D10/(1000*F10)) | J10: =IF(OR(I10="",C10="",N(C10)<=0),"",I10/C10) | K10: =IF(OR(J10="",G10=""),"",IF(J10<=G10,"OK","NG")) | L10: =IF(OR(H10="",D10="",E10="",C10="",G10="",N(C10)<=0,N(G10)<=0),"",H10*E10*D10/(1000*C10*G10)) | M10: =IF(L10="","",IF(L10>MAX(参照表!$A$12:$A$24),"要検討",INDEX(参照表!$A$12:$A$24,COUNTIF(参照表!$A$12:$A$24,"<"&L10)+1)))
H11: =IFERROR(INDEX(参照表!$B$5:$B$7,MATCH(B11,参照表!$A$5:$A$7,0)),"") | I11: =IF(OR(B11="",D11="",E11="",F11="",N(F11)<=0),"",H11*E11*D11/(1000*F11)) | J11: =IF(OR(I11="",C11="",N(C11)<=0),"",I11/C11) | K11: =IF(OR(J11="",G11=""),"",IF(J11<=G11,"OK","NG")) | L11: =IF(OR(H11="",D11="",E11="",C11="",G11="",N(C11)<=0,N(G11)<=0),"",H11*E11*D11/(1000*C11*G11)) | M11: =IF(L11="","",IF(L11>MAX(参照表!$A$12:$A$24),"要検討",INDEX(参照表!$A$12:$A$24,COUNTIF(参照表!$A$12:$A$24,"<"&L11)+1)))
H12: =IFERROR(INDEX(参照表!$B$5:$B$7,MATCH(B12,参照表!$A$5:$A$7,0)),"") | I12: =IF(OR(B12="",D12="",E12="",F12="",N(F12)<=0),"",H12*E12*D12/(1000*F12)) | J12: =IF(OR(I12="",C12="",N(C12)<=0),"",I12/C12) | K12: =IF(OR(J12="",G12=""),"",IF(J12<=G12,"OK","NG")) | L12: =IF(OR(H12="",D12="",E12="",C12="",G12="",N(C12)<=0,N(G12)<=0),"",H12*E12*D12/(1000*C12*G12)) | M12: =IF(L12="","",IF(L12>MAX(参照表!$A$12:$A$24),"要検討",INDEX(参照表!$A$12:$A$24,COUNTIF(参照表!$A$12:$A$24,"<"&L12)+1)))
H13: =IFERROR(INDEX(参照表!$B$5:$B$7,MATCH(B13,参照表!$A$5:$A$7,0)),"") | I13: =IF(OR(B13="",D13="",E13="",F13="",N(F13)<=0),"",H13*E13*D13/(1000*F13)) | J13: =IF(OR(I13="",C13="",N(C13)<=0),"",I13/C13) | K13: =IF(OR(J13="",G13=""),"",IF(J13<=G13,"OK","NG")) | L13: =IF(OR(H13="",D13="",E13="",C13="",G13="",N(C13)<=0,N(G13)<=0),"",H13*E13*D13/(1000*C13*G13)) | M13: =IF(L13="","",IF(L13>MAX(参照表!$A$12:$A$24),"要検討",INDEX(参照表!$A$12:$A$24,COUNTIF(参照表!$A$12:$A$24,"<"&L13)+1)))
H14: =IFERROR(INDEX(参照表!$B$5:$B$7,MATCH(B14,参照表!$A$5:$A$7,0)),"") | I14: =IF(OR(B14="",D14="",E14="",F14="",N(F14)<=0),"",H14*E14*D14/(1000*F14)) | J14: =IF(OR(I14="",C14="",N(C14)<=0),"",I14/C14) | K14: =IF(OR(J14="",G14=""),"",IF(J14<=G14,"OK","NG")) | L14: =IF(OR(H14="",D14="",E14="",C14="",G14="",N(C14)<=0,N(G14)<=0),"",H14*E14*D14/(1000*C14*G14)) | M14: =IF(L14="","",IF(L14>MAX(参照表!$A$12:$A$24),"要検討",INDEX(参照表!$A$12:$A$24,COUNTIF(参照表!$A$12:$A$24,"<"&L14)+1)))
H15: =IFERROR(INDEX(参照表!$B$5:$B$7,MATCH(B15,参照表!$A$5:$A$7,0)),"") | I15: =IF(OR(B15="",D15="",E15="",F15="",N(F15)<=0),"",H15*E15*D15/(1000*F15)) | J15: =IF(OR(I15="",C15="",N(C15)<=0),"",I15/C15) | K15: =IF(OR(J15="",G15=""),"",IF(J15<=G15,"OK","NG")) | L15: =IF(OR(H15="",D15="",E15="",C15="",G15="",N(C15)<=0,N(G15)<=0),"",H15*E15*D15/(1000*C15*G15)) | M15: =IF(L15="","",IF(L15>MAX(参照表!$A$12:$A$24),"要検討",INDEX(参照表!$A$12:$A$24,COUNTIF(参照表!$A$12:$A$24,"<"&L15)+1)))
H16: =IFERROR(INDEX(参照表!$B$5:$B$7,MATCH(B16,参照表!$A$5:$A$7,0)),"") | I16: =IF(OR(B16="",D16="",E16="",F16="",N(F16)<=0),"",H16*E16*D16/(1000*F16)) | J16: =IF(OR(I16="",C16="",N(C16)<=0),"",I16/C16) | K16: =IF(OR(J16="",G16=""),"",IF(J16<=G16,"OK","NG")) | L16: =IF(OR(H16="",D16="",E16="",C16="",G16="",N(C16)<=0,N(G16)<=0),"",H16*E16*D16/(1000*C16*G16)) | M16: =IF(L16="","",IF(L16>MAX(参照表!$A$12:$A$24),"要検討",INDEX(参照表!$A$12:$A$24,COUNTIF(参照表!$A$12:$A$24,"<"&L16)+1)))
H17: =IFERROR(INDEX(参照表!$B$5:$B$7,MATCH(B17,参照表!$A$5:$A$7,0)),"") | I17: =IF(OR(B17="",D17="",E17="",F17="",N(F17)<=0),"",H17*E17*D17/(1000*F17)) | J17: =IF(OR(I17="",C17="",N(C17)<=0),"",I17/C17) | K17: =IF(OR(J17="",G17=""),"",IF(J17<=G17,"OK","NG")) | L17: =IF(OR(H17="",D17="",E17="",C17="",G17="",N(C17)<=0,N(G17)<=0),"",H17*E17*D17/(1000*C17*G17)) | M17: =IF(L17="","",IF(L17>MAX(参照表!$A$12:$A$24),"要検討",INDEX(参照表!$A$12:$A$24,COUNTIF(参照表!$A$12:$A$24,"<"&L17)+1)))
H18: =IFERROR(INDEX(参照表!$B$5:$B$7,MATCH(B18,参照表!$A$5:$A$7,0)),"") | I18: =IF(OR(B18="",D18="",E18="",F18="",N(F18)<=0),"",H18*E18*D18/(1000*F18)) | J18: =IF(OR(I18="",C18="",N(C18)<=0),"",I18/C18) | K18: =IF(OR(J18="",G18=""),"",IF(J18<=G18,"OK","NG")) | L18: =IF(OR(H18="",D18="",E18="",C18="",G18="",N(C18)<=0,N(G18)<=0),"",H18*E18*D18/(1000*C18*G18)) | M18: =IF(L18="","",IF(L18>MAX(参照表!$A$12:$A$24),"要検討",INDEX(参照表!$A$12:$A$24,COUNTIF(参照表!$A$12:$A$24,"<"&L18)+1)))
... H25: =IFERROR(INDEX(参照表!$B$5:$B$7,MATCH(B25,参照表!$A$5:$A$7,0)),"") | I25: =IF(OR(B25="",D25="",E25="",F25="",N(F25)<=0),"",H25*E25*D25/(1000*F25)) | J25: =IF(OR(I25="",C25="",N(C25)<=0),"",I25/C25) | K25: =IF(OR(J25="",G25=""),"",IF(J25<=G25,"OK","NG")) | L25: =IF(OR(H25="",D25="",E25="",C25="",G25="",N(C25)<=0,N(G25)<=0),"",H25*E25*D25/(1000*C25*G25)) | M25: =IF(L25="","",IF(L25>MAX(参照表!$A$12:$A$24),"要検討",INDEX(参照表!$A$12:$A$24,COUNTIF(参照表!$A$12:$A$24,"<"&L25)+1)))
A27: 【免責】本ツールは設計・積算の補助を目的とした概算ツールです。最終判断は最新の電気設備技術基準・同解釈・内線規程・メーカー資料・所轄電力会社の規定に基づき、有資格者が行ってください。

Sheet 許容電流
A1: 許容電流（電流減少係数・周囲温度補正）
A2: 凡例: 黄色セル（青字）＝入力欄 ／ 水色セル＝自動計算 ／ それ以外は触らないでください
A3: 許容電流 = 基準値 × 電流減少係数 × 温度補正係数√((60-θ)/30) （小数点以下1位を7捨8入／ビニル絶縁60℃）
A5: 回路名 | B5: 電線 | C5: 同一管内の電線数 | D5: 周囲温度 ℃ | E5: 負荷電流 A | F5: 基準値 A | G5: 減少係数 | H5: 温度補正 | I5: 許容電流 A | J5: 判定
A6: 例）エアコン回路 | B6: 単線 2.0mm | C6: 3本以下 | D6: 30 | E6: 16 | F6: =IFERROR(INDEX(参照表!$B$29:$B$41,MATCH(B6,参照表!$A$29:$A$41,0)),"") | G6: =IFERROR(INDEX(参照表!$B$46:$B$53,MATCH(C6,参照表!$A$46:$A$53,0)),"") | H6: =IF(D6="",1,IF(D6>=60,0,SQRT((60-MAX(D6,30))/30))) | I6: =IF(OR(F6="",G6=""),"",INT(ROUNDDOWN(ROUND(F6*G6*H6,6),1)+0.2+1E-9)) | J6: =IF(OR(I6="",E6=""),"",IF(E6<=I6,"OK","NG"))
F7: =IFERROR(INDEX(参照表!$B$29:$B$41,MATCH(B7,参照表!$A$29:$A$41,0)),"") | G7: =IFERROR(INDEX(参照表!$B$46:$B$53,MATCH(C7,参照表!$A$46:$A$53,0)),"") | H7: =IF(D7="",1,IF(D7>=60,0,SQRT((60-MAX(D7,30))/30))) | I7: =IF(OR(F7="",G7=""),"",INT(ROUNDDOWN(ROUND(F7*G7*H7,6),1)+0.2+1E-9)) | J7: =IF(OR(I7="",E7=""),"",IF(E7<=I7,"OK","NG"))
F8: =IFERROR(INDEX(参照表!$B$29:$B$41,MATCH(B8,参照表!$A$29:$A$41,0)),"") | G8: =IFERROR(INDEX(参照表!$B$46:$B$53,MATCH(C8,参照表!$A$46:$A$53,0)),"") | H8: =IF(D8="",1,IF(D8>=60,0,SQRT((60-MAX(D8,30))/30))) | I8: =IF(OR(F8="",G8=""),"",INT(ROUNDDOWN(ROUND(F8*G8*H8,6),1)+0.2+1E-9)) | J8: =IF(OR(I8="",E8=""),"",IF(E8<=I8,"OK","NG"))
F9: =IFERROR(INDEX(参照表!$B$29:$B$41,MATCH(B9,参照表!$A$29:$A$41,0)),"") | G9: =IFERROR(INDEX(参照表!$B$46:$B$53,MATCH(C9,参照表!$A$46:$A$53,0)),"") | H9: =IF(D9="",1,IF(D9>=60,0,SQRT((60-MAX(D9,30))/30))) | I9: =IF(OR(F9="",G9=""),"",INT(ROUNDDOWN(ROUND(F9*G9*H9,6),1)+0.2+1E-9)) | J9: =IF(OR(I9="",E9=""),"",IF(E9<=I9,"OK","NG"))
F10: =IFERROR(INDEX(参照表!$B$29:$B$41,MATCH(B10,参照表!$A$29:$A$41,0)),"") | G10: =IFERROR(INDEX(参照表!$B$46:$B$53,MATCH(C10,参照表!$A$46:$A$53,0)),"") | H10: =IF(D10="",1,IF(D10>=60,0,SQRT((60-MAX(D10,30))/30))) | I10: =IF(OR(F10="",G10=""),"",INT(ROUNDDOWN(ROUND(F10*G10*H10,6),1)+0.2+1E-9)) | J10: =IF(OR(I10="",E10=""),"",IF(E10<=I10,"OK","NG"))
F11: =IFERROR(INDEX(参照表!$B$29:$B$41,MATCH(B11,参照表!$A$29:$A$41,0)),"") | G11: =IFERROR(INDEX(参照表!$B$46:$B$53,MATCH(C11,参照表!$A$46:$A$53,0)),"") | H11: =IF(D11="",1,IF(D11>=60,0,SQRT((60-MAX(D11,30))/30))) | I11: =IF(OR(F11="",G11=""),"",INT(ROUNDDOWN(ROUND(F11*G11*H11,6),1)+0.2+1E-9)) | J11: =IF(OR(I11="",E11=""),"",IF(E11<=I11,"OK","NG"))
F12: =IFERROR(INDEX(参照表!$B$29:$B$41,MATCH(B12,参照表!$A$29:$A$41,0)),"") | G12: =IFERROR(INDEX(参照表!$B$46:$B$53,MATCH(C12,参照表!$A$46:$A$53,0)),"") | H12: =IF(D12="",1,IF(D12>=60,0,SQRT((60-MAX(D12,30))/30))) | I12: =IF(OR(F12="",G12=""),"",INT(ROUNDDOWN(ROUND(F12*G12*H12,6),1)+0.2+1E-9)) | J12: =IF(OR(I12="",E12=""),"",IF(E12<=I12,"OK","NG"))
F13: =IFERROR(INDEX(参照表!$B$29:$B$41,MATCH(B13,参照表!$A$29:$A$41,0)),"") | G13: =IFERROR(INDEX(参照表!$B$46:$B$53,MATCH(C13,参照表!$A$46:$A$53,0)),"") | H13: =IF(D13="",1,IF(D13>=60,0,SQRT((60-MAX(D13,30))/30))) | I13: =IF(OR(F13="",G13=""),"",INT(ROUNDDOWN(ROUND(F13*G13*H13,6),1)+0.2+1E-9)) | J13: =IF(OR(I13="",E13=""),"",IF(E13<=I13,"OK","NG"))
F14: =IFERROR(INDEX(参照表!$B$29:$B$41,MATCH(B14,参照表!$A$29:$A$41,0)),"") | G14: =IFERROR(INDEX(参照表!$B$46:$B$53,MATCH(C14,参照表!$A$46:$A$53,0)),"") | H14: =IF(D14="",1,IF(D14>=60,0,SQRT((60-MAX(D14,30))/30))) | I14: =IF(OR(F14="",G14=""),"",INT(ROUNDDOWN(ROUND(F14*G14*H14,6),1)+0.2+1E-9)) | J14: =IF(OR(I14="",E14=""),"",IF(E14<=I14,"OK","NG"))
F15: =IFERROR(INDEX(参照表!$B$29:$B$41,MATCH(B15,参照表!$A$29:$A$41,0)),"") | G15: =IFERROR(INDEX(参照表!$B$46:$B$53,MATCH(C15,参照表!$A$46:$A$53,0)),"") | H15: =IF(D15="",1,IF(D15>=60,0,SQRT((60-MAX(D15,30))/30))) | I15: =IF(OR(F15="",G15=""),"",INT(ROUNDDOWN(ROUND(F15*G15*H15,6),1)+0.2+1E-9)) | J15: =IF(OR(I15="",E15=""),"",IF(E15<=I15,"OK","NG"))
F16: =IFERROR(INDEX(参照表!$B$29:$B$41,MATCH(B16,参照表!$A$29:$A$41,0)),"") | G16: =IFERROR(INDEX(参照表!$B$46:$B$53,MATCH(C16,参照表!$A$46:$A$53,0)),"") | H16: =IF(D16="",1,IF(D16>=60,0,SQRT((60-MAX(D16,30))/30))) | I16: =IF(OR(F16="",G16=""),"",INT(ROUNDDOWN(ROUND(F16*G16*H16,6),1)+0.2+1E-9)) | J16: =IF(OR(I16="",E16=""),"",IF(E16<=I16,"OK","NG"))
F17: =IFERROR(INDEX(参照表!$B$29:$B$41,MATCH(B17,参照表!$A$29:$A$41,0)),"") | G17: =IFERROR(INDEX(参照表!$B$46:$B$53,MATCH(C17,参照表!$A$46:$A$53,0)),"") | H17: =IF(D17="",1,IF(D17>=60,0,SQRT((60-MAX(D17,30))/30))) | I17: =IF(OR(F17="",G17=""),"",INT(ROUNDDOWN(ROUND(F17*G17*H17,6),1)+0.2+1E-9)) | J17: =IF(OR(I17="",E17=""),"",IF(E17<=I17,"OK","NG"))
F18: =IFERROR(INDEX(参照表!$B$29:$B$41,MATCH(B18,参照表!$A$29:$A$41,0)),"") | G18: =IFERROR(INDEX(参照表!$B$46:$B$53,MATCH(C18,参照表!$A$46:$A$53,0)),"") | H18: =IF(D18="",1,IF(D18>=60,0,SQRT((60-MAX(D18,30))/30))) | I18: =IF(OR(F18="",G18=""),"",INT(ROUNDDOWN(ROUND(F18*G18*H18,6),1)+0.2+1E-9)) | J18: =IF(OR(I18="",E18=""),"",IF(E18<=I18,"OK","NG"))
... F20: =IFERROR(INDEX(参照表!$B$29:$B$41,MATCH(B20,参照表!$A$29:$A$41,0)),"") | G20: =IFERROR(INDEX(参照表!$B$46:$B$53,MATCH(C20,参照表!$A$46:$A$53,0)),"") | H20: =IF(D20="",1,IF(D20>=60,0,SQRT((60-MAX(D20,30))/30))) | I20: =IF(OR(F20="",G20=""),"",INT(ROUNDDOWN(ROUND(F20*G20*H20,6),1)+0.2+1E-9)) | J20: =IF(OR(I20="",E20=""),"",IF(E20<=I20,"OK","NG"))
A22: ※7捨8入: 小数点以下1位が7以下は切り捨て、8以上は切り上げ（例 27×0.70=18.9→19A）
A23: 【免責】本ツールは設計・積算の補助を目的とした概算ツールです。最終判断は最新の電気設備技術基準・同解釈・内線規程・メーカー資料・所轄電力会社の規定に基づき、有資格者が行ってください。

Sheet 材料拾い
A1: 材料拾い出し表（部屋・回路ごとに数量を入れると合計と材料費が出ます）
A2: 凡例: 黄色セル（青字）＝入力欄 ／ 水色セル＝自動計算 ／ それ以外は触らないでください
A5: 品名 | B5: 規格 | C5: 単位 | D5: ロス率 | E5: 1F LDK | F5: 1F 水回り | G5: 2F 洋室 | H5: 屋外 | I5: 区画5 | J5: 区画6 | K5: 区画7 | L5: 区画8 | M5: 合計数量 | N5: 単価 円 | O5: 金額 円
A6: VVFケーブル | B6: 2.0-3C | C6: m | D6: 0.1 | E6: 18 | F6: 6 | G6: 22 | H6: 5 | M6: =IF(COUNT(E6:L6)=0,"",ROUNDUP(ROUND(SUM(E6:L6)*(1+N(D6)),6),0)) | N6: 185 | O6: =IF(OR(M6="",N6=""),"",M6*N6)
A7: VVFケーブル | B7: 1.6-2C | C7: m | D7: 0.1 | E7: 30 | F7: 12 | G7: 25 | H7: 0 | M7: =IF(COUNT(E7:L7)=0,"",ROUNDUP(ROUND(SUM(E7:L7)*(1+N(D7)),6),0)) | N7: 95 | O7: =IF(OR(M7="",N7=""),"",M7*N7)
A8: 埋込スイッチ | B8: 片切 | C8: 個 | D8: 0 | E8: 2 | F8: 1 | G8: 2 | H8: 0 | M8: =IF(COUNT(E8:L8)=0,"",ROUNDUP(ROUND(SUM(E8:L8)*(1+N(D8)),6),0)) | N8: 180 | O8: =IF(OR(M8="",N8=""),"",M8*N8)
A9: 埋込コンセント | B9: 2口 接地付 | C9: 個 | D9: 0 | E9: 4 | F9: 2 | G9: 3 | H9: 1 | M9: =IF(COUNT(E9:L9)=0,"",ROUNDUP(ROUND(SUM(E9:L9)*(1+N(D9)),6),0)) | N9: 420 | O9: =IF(OR(M9="",N9=""),"",M9*N9)
A10: PF管 | B10: 16 | C10: m | D10: 0.05 | E10: 0 | F10: 0 | G10: 0 | H10: 8 | M10: =IF(COUNT(E10:L10)=0,"",ROUNDUP(ROUND(SUM(E10:L10)*(1+N(D10)),6),0)) | N10: 60 | O10: =IF(OR(M10="",N10=""),"",M10*N10)
M11: =IF(COUNT(E11:L11)=0,"",ROUNDUP(ROUND(SUM(E11:L11)*(1+N(D11)),6),0)) | O11: =IF(OR(M11="",N11=""),"",M11*N11)
M12: =IF(COUNT(E12:L12)=0,"",ROUNDUP(ROUND(SUM(E12:L12)*(1+N(D12)),6),0)) | O12: =IF(OR(M12="",N12=""),"",M12*N12)
M13: =IF(COUNT(E13:L13)=0,"",ROUNDUP(ROUND(SUM(E13:L13)*(1+N(D13)),6),0)) | O13: =IF(OR(M13="",N13=""),"",M13*N13)
M14: =IF(COUNT(E14:L14)=0,"",ROUNDUP(ROUND(SUM(E14:L14)*(1+N(D14)),6),0)) | O14: =IF(OR(M14="",N14=""),"",M14*N14)
M15: =IF(COUNT(E15:L15)=0,"",ROUNDUP(ROUND(SUM(E15:L15)*(1+N(D15)),6),0)) | O15: =IF(OR(M15="",N15=""),"",M15*N15)
M16: =IF(COUNT(E16:L16)=0,"",ROUNDUP(ROUND(SUM(E16:L16)*(1+N(D16)),6),0)) | O16: =IF(OR(M16="",N16=""),"",M16*N16)
M17: =IF(COUNT(E17:L17)=0,"",ROUNDUP(ROUND(SUM(E17:L17)*(1+N(D17)),6),0)) | O17: =IF(OR(M17="",N17=""),"",M17*N17)
M18: =IF(COUNT(E18:L18)=0,"",ROUNDUP(ROUND(SUM(E18:L18)*(1+N(D18)),6),0)) | O18: =IF(OR(M18="",N18=""),"",M18*N18)
M19: =IF(COUNT(E19:L19)=0,"",ROUNDUP(ROUND(SUM(E19:L19)*(1+N(D19)),6),0)) | O19: =IF(OR(M19="",N19=""),"",M19*N19)
M20: =IF(COUNT(E20:L20)=0,"",ROUNDUP(ROUND(SUM(E20:L20)*(1+N(D20)),6),0)) | O20: =IF(OR(M20="",N20=""),"",M20*N20)
M21: =IF(COUNT(E21:L21)=0,"",ROUNDUP(ROUND(SUM(E21:L21)*(1+N(D21)),6),0)) | O21: =IF(OR(M21="",N21=""),"",M21*N21)
M22: =IF(COUNT(E22:L22)=0,"",ROUNDUP(ROUND(SUM(E22:L22)*(1+N(D22)),6),0)) | O22: =IF(OR(M22="",N22=""),"",M22*N22)
... M35: =IF(COUNT(E35:L35)=0,"",ROUNDUP(ROUND(SUM(E35:L35)*(1+N(D35)),6),0)) | O35: =IF(OR(M35="",N35=""),"",M35*N35)
N36: 材料費計 | O36: =SUM(O6:O35)
A38: ※例の単価はダミーです。仕入れ値に置き換えてください。ロス率は切断・端末処理分の割増し。

Sheet 見積書
A1: 御 見 積 書
A3: 宛先 | B3: ○○ 様 | E3: 見積日 | F3: =TODAY()
A4: 件名 | B4: ○○邸 電気設備工事 | E4: 有効期限 | F4: 発行日より30日
A6: 御見積金額（税込） | E6: 会社名 | F6: ○○電設
B7: =G34 | E7: 登録番号 | F7: T0000000000000
E8: 連絡先 | F8: 000-0000-0000
A11: No | B11: 品名・工事内容 | C11: 規格 | D11: 数量 | E11: 単位 | F11: 単価 | G11: 金額
A12: 1 | B12: 材料費一式（材料拾い表より） | D12: 1 | E12: 式 | F12: =材料拾い!O36 | G12: =IF(OR(D12="",F12=""),"",ROUND(D12*F12,0))
A13: 2 | B13: 配線工事（労務費） | C13: 電工 | D13: 2.5 | E13: 人工 | F13: 25000 | G13: =IF(OR(D13="",F13=""),"",ROUND(D13*F13,0))
A14: 3 | B14: 器具取付費 | D14: 12 | E14: 箇所 | F14: 1500 | G14: =IF(OR(D14="",F14=""),"",ROUND(D14*F14,0))
A15: 4 | B15: 諸経費 | D15: 1 | E15: 式 | F15: 8000 | G15: =IF(OR(D15="",F15=""),"",ROUND(D15*F15,0))
A16: 5 | G16: =IF(OR(D16="",F16=""),"",ROUND(D16*F16,0))
A17: 6 | G17: =IF(OR(D17="",F17=""),"",ROUND(D17*F17,0))
A18: 7 | G18: =IF(OR(D18="",F18=""),"",ROUND(D18*F18,0))
A19: 8 | G19: =IF(OR(D19="",F19=""),"",ROUND(D19*F19,0))
A20: 9 | G20: =IF(OR(D20="",F20=""),"",ROUND(D20*F20,0))
A21: 10 | G21: =IF(OR(D21="",F21=""),"",ROUND(D21*F21,0))
A22: 11 | G22: =IF(OR(D22="",F22=""),"",ROUND(D22*F22,0))
A23: 12 | G23: =IF(OR(D23="",F23=""),"",ROUND(D23*F23,0))
A24: 13 | G24: =IF(OR(D24="",F24=""),"",ROUND(D24*F24,0))
A25: 14 | G25: =IF(OR(D25="",F25=""),"",ROUND(D25*F25,0))
A26: 15 | G26: =IF(OR(D26="",F26=""),"",ROUND(D26*F26,0))
A27: 16 | G27: =IF(OR(D27="",F27=""),"",ROUND(D27*F27,0))
... A31: 20 | G31: =IF(OR(D31="",F31=""),"",ROUND(D31*F31,0))
F32: 小計 | G32: =SUM(G12:G31)
E33: 0.1 | F33: 消費税 | G33: =ROUNDDOWN(G32*E33,0)
F34: 合計 | G34: =G32+G33
A36: 備考 | B36: ・既設配線の不良等、追加工事が必要な場合は別途お見積りいたします。

Sheet 参照表
A1: 参照表（計算シートから参照しています。数値を変える場合は最新の基準で確認のうえ）
A3: ① 配電方式と電圧降下の係数K（e = K×L×I ÷ (1000×A)）
A4: 配電方式 | B4: 係数K
A5: 単相2線式 | B5: 35.6 | C5: 単相3線式は中性線と外線の間の降下（平衡負荷）
A6: 単相3線式 | B6: 17.8
A7: 三相3線式 | B7: 30.8
A10: ② 標準電線断面積（mm²）
A11: 断面積mm²
A12: 2 | B12: 単線の断面積: 1.6mm=2.0 / 2.0mm=3.14 / 2.6mm=5.31 / 3.2mm=8.04 mm²
A13: 3.5
A14: 5.5
A15: 8
A16: 14
A17: 22
A18: 38
A19: 60
A20: 100
A21: 150
A22: 200
A23: 250
A24: 325
A27: ③ 許容電流（電技解釈 表146-1 基準値・周囲温度30℃）
A28: 電線 | B28: 許容電流A
A29: 単線 1.6mm | B29: 27
A30: 単線 2.0mm | B30: 35
A31: 単線 2.6mm | B31: 48
A32: 単線 3.2mm | B32: 62
A33: より線 2mm² | B33: 27
A34: より線 3.5mm² | B34: 37
A35: より線 5.5mm² | B35: 49
A36: より線 8mm² | B36: 61
A37: より線 14mm² | B37: 88
A38: より線 22mm² | B38: 115
A39: より線 38mm² | B39: 162
A40: より線 60mm² | B40: 217
A41: より線 100mm² | B41: 298
A44: ④ 電流減少係数（電技解釈 表146-3）
A45: 同一管内の電線数 | B45: 係数
A46: 管に収めない（がいし引き等） | B46: 1
A47: 3本以下 | B47: 0.7
...
